Workbook
Name approvedby: #REF!
Name APPROVER1: #REF!
Name APPROVER2: #REF!
Name APPROVER2A: #REF!
Name APPROVER3: #REF!
Name APPROVER3a: #REF!
Name APPROVER4: #REF!
Name APPROVER5: #REF!
Name APPROVER6: #REF!
Name APPROVER7: #REF!
Name APPROVER8: #REF!
Name CONAME: #REF!
Name EFFECTIVEDATE: #REF!
Name ISSUEDBY: #REF!
Name k: #REF!
Name supercedes: #REF!
Name title: #REF!

Sheet All
I1: =2012-17 -> 1995 | K1: =2015-23 -> 1992 | T1: =NOW() -> 46315.632 | BL1: 3 | BM1: 3 | BN1: 2 | BO1: 3 | BP1: 3 | BQ1: 3 | BR1: 3 | BS1: 2 | BT1: 3 | BU1: 1 | BV1: 3 | BW1: 2 | BX1: 3 | BY1: 2 | BZ1: 2 | CA1: 2 | CB1: 2 | CC1: 2 | CD1: 2 | CE1: 2 | CF1: 1 | CG1: 2 | CH1: 1 | CI1: 1 | CR1: =8/12 -> 0.66666667 | DB1: =6/7 -> 0.85714286
G2: 2026
B3: Count | C3: Chat Status | D3: Chat Date | E3: Name | F3: Staff ID | G3: Age | H3: Birth Year | I3: Gender | J3: Nationality | K3: Department | L3: Section Name | M3: Unit Name | N3: Sub Unit | O3: Staff Position | P3: Email Address | Q3: Employment Category | R3: Contract Expire Date | S3: Joining Date | T3: Years in PET | U3: Years of RE Experience | V3: SG | W3: Age Promoted to Staff or Principal | X3: Years in Salary Grade | Y3: Date of Appointment to Current Grade | Z3: Current Location: | AA3: Date in Position | AB3: Length in Current Assignment | AC3: Assessment Level | AD3: Last Assesment Date | AE3: Ruler Type | AF3: Potential | AG3: Background | AH3: Strength | AI3: Recommendation | AJ3: Resource/SME | AK3: Interest | AL3: Preference | AM3: Comment/Suggestion | AN3: B1 | AO3: B2 | AP3: B3 | AQ3: B4 | AR3: B5 | AS3: B6 | AT3: B7 | AU3: B8 | AV3: B9 | AW3: B10 | AX3: B11 | AY3: B12 | AZ3: K1 | BA3: K2 | BB3: K3 | BC3: K4 | BD3: K5 | BE3: P1 | BF3: P2 | BG3: P3 | BH3: P4 | BI3: P5 | BJ3: E1 | BK3: E2 | BL3: R-B1 | BM3: R-B2 | BN3: R-B3 | BO3: R-B4 | BP3: R-B5 | BQ3: R-B6 | BR3: R-B7 | BS3: R-B8 | BT3: R-B9 | BU3: R-B10 | BV3: R-B11 | BW3: R-B12 | BX3: R-K1 | BY3: R-K2 | BZ3: R-K3 | CA3: R-K4 | CB3: R-K5 | CC3: R-P1 | CD3: R-P2 | CE3: R-P3 | CF3: R-P4 | CG3: R-P5 | CH3: R-E1 | CI3: R-E2 | CJ3: G-B1 | CK3: G-B2 | CL3: G-B3 | CM3: G-B4 | CN3: G-B5 | CO3: G-B6 | CP3: G-B7 | CQ3: G-B8 | CR3: G-B9 | CS3: G-B10 | CT3: G-B11 | CU3: G-B12 | CV3: G-K1 | CW3: G-K2 | CX3: G-K3 | CY3: G-K4 | CZ3: G-K5 | DA3: G-P1 | DB3: G-P2 | DC3: G-P3 | DD3: G-P4 | DE3: G-P5 | DF3: G-E1 | DG3: G-E2 | DH3: Next Grade Base | DI3: Next Grade Keys | DJ3: Next Grade Pacing | DK3: Next Grade Emerging | DL3: Next Grade CTI | DM3: Staff Base2 | DN3: Staff Keys3 | DO3: Staff Pacing4 | DP3: Staff Emerging5 | DQ3: Staff CTI6 | DR3: Principal Base | DS3: Principal Keys | DT3: Principal Pacing | DU3: Principal Emerging | DV3: Principal CTI | DW3: Custodian Base | DX3: Custodian Keys | DY3: Custodian Pacing | DZ3: Custodian Emerging | EA3: Custodian CTI | EB3: Assesor1 | EC3: Assessor2 | ED3: Supervisor | EE3: Remarks
B4: 1 | C4: Yes | D4: 46147 | E4: Abdul Hakim bin Ameludin | F4: 1019423 | G4: =($T$1-H4)/365 -> 36.82639 | H4: 32874 | I4: M | J4: Malaysia | K4: DPE | L4: RMS | M4: SBA | N4: Cluster 2 | O4: Executive | P4: hakim.ameludin@petronas.com.my | Q4: Permanent | S4: 41674 | T4: =YEARFRAC(S4,$T$1) -> 12.711111 | U4: =Table9[[#This Row],[Years in PET]] -> 12.711111 | V4: P3 | X4: =($T$1-Table9[[#This Row],[Date of Appointment to Current Grade]])/365 -> 1.5551569 | Y4: 45748 | Z4: SBA | AA4: 45658 | AB4: =($T$1-Table9[[#This Row],[Date in Position]])/365 -> 1.8017322 | AC4: UPE | AD4: 45689 | AE4: RDP | AF4: Average | AH4: ✅ FDP + Project Maturation governance ✅ MBAL+IAM, ✅ PVT/fluid characterization | AI4: Keep track competencies agaisnt next level | AJ4: Analytical, PVT | AK4: Study , PEI, DRO Choose RDP path | AL4: TP | AN4: 2 | AO4: 1 | AP4: 1 | AQ4: 2 | AR4: 2 | AS4: 2 | AT4: 2 | AU4: 2 | AV4: 1 | AW4: 1 | AX4: 1 | AY4: 1 | AZ4: 2 | BA4: 1 | BB4: 0 | BC4: 1 | BD4: 0 | BE4: 1 | BF4: 2 | BG4: 2 | BH4: 2 | BI4: 0 | BJ4: 0 | BK4: 0 | BL4: =IF(AND(All!$V4="P1",All!$AE4="RDP"),Ruler!E$6,IF(AND(All!$V4="P2",All!$AE4="RDP"),Ruler!E$7,IF(AND(All!$V4="P3",All!$AE4="RDP"),Ruler!E$8,IF(AND(All!$V4="P4",All!$AE4="RDP"),Ruler!E$9,IF(AND(All!$V4="P5",All!$AE4="RDP"),Ruler!E$10,IF(AND(All!$V4="P6",All!$AE4="RDP"),Ruler!E$11,IF(AND(All!$V4="P7",All!$AE4="RDP"),Ruler!E$12,IF(AND(All!$V4="P8",All!$AE4="RDP"),Ruler!E$13,IF(AND(All!$V4="P9",All!$AE4="RDP"),Ruler!E$14,IF(AND(All!$V4="P1",All!$AE4="RMS"),Ruler!E$6,IF(AND(All!$V4="P2",All!$AE4="RMS"),Ruler!E$15,IF(AND(All!$V4="P3",All!$AE4="RMS"),Ruler!E$16,IF(AND(All!$V4="P4",All!$AE4="RMS"),Ruler!E$17,IF(AND(All!$V4="P5",All!$AE4="RMS"),Ruler!E$18,IF(AND(All!$V4="P6",All!$AE4="RMS"),Ruler!E$19,IF(AND(All!$V4="P7",All!$AE4="RMS"),Ruler!E$20,IF(AND(All!$V4="P8",All!$AE4="RMS"),Ruler!E$21,IF(AND(All!$V4="P9",All!$AE4="RMS"),Ruler!E$22,IF(AND(All!$V4="P1",All!$AE4="RSS"),Ruler!E$6,IF(AND(All!$V4="P2",All!$AE4="RSS"),Ruler!E$23,IF(AND(All!$V4="P3",All!$AE4="RSS"),Ruler!E$24,IF(AND(All!$V4="P4",All!$AE4="RSS"),Ruler!E$25,IF(AND(All!$V4="P5",All!$AE4="RSS"),Ruler!E$26,IF(AND(All!$V4="P6",All!$AE4="RSS"),Ruler!E$27,IF(AND(All!$V4="P7",All!$AE4="RSS"),Ruler!E$28,IF(AND(All!$V4="P8",All!$AE4="RSS"),Ruler!E$29,IF(AND(All!$V4="P9",All!$AE4="RSS"),Ruler!E$30,0))))))))))))))))))))))))))) -> 2 | BM4: =IF(AND(All!$V4="P1",All!$AE4="RDP"),Ruler!F$6,IF(AND(All!$V4="P2",All!$AE4="RDP"),Ruler!F$7,IF(AND(All!$V4="P3",All!$AE4="RDP"),Ruler!F$8,IF(AND(All!$V4="P4",All!$AE4="RDP"),Ruler!F$9,IF(AND(All!$V4="P5",All!$AE4="RDP"),Ruler!F$10,IF(AND(All!$V4="P6",All!$AE4="RDP"),Ruler!F$11,IF(AND(All!$V4="P7",All!$AE4="RDP"),Ruler!F$12,IF(AND(All!$V4="P8",All!$AE4="RDP"),Ruler!F$13,IF(AND(All!$V4="P9",All!$AE4="RDP"),Ruler!F$14,IF(AND(All!$V4="P1",All!$AE4="RMS"),Ruler!F$6,IF(AND(All!$V4="P2",All!$AE4="RMS"),Ruler!F$15,IF(AND(All!$V4="P3",All!$AE4="RMS"),Ruler!F$16,IF(AND(All!$V4="P4",All!$AE4="RMS"),Ruler!F$17,IF(AND(All!$V4="P5",All!$AE4="RMS"),Ruler!F$18,IF(AND(All!$V4="P6",All!$AE4="RMS"),Ruler!F$19,IF(AND(All!$V4="P7",All!$AE4="RMS"),Ruler!F$20,IF(AND(All!$V4="P8",All!$AE4="RMS"),Ruler!F$21,IF(AND(All!$V4="P9",All!$AE4="RMS"),Ruler!F$22,IF(AND(All!$V4="P1",All!$AE4="RSS"),Ruler!F$6,IF(AND(All!$V4="P2",All!$AE4="RSS"),Ruler!F$23,IF(AND(All!$V4="P3",All!$AE4="RSS"),Ruler!F$24,IF(AND(All!$V4="P4",All!$AE4="RSS"),Ruler!F$25,IF(AND(All!$V4="P5",All!$AE4="RSS"),Ruler!F$26,IF(AND(All!$V4="P6",All!$AE4="RSS"),Ruler!F$27,IF(AND(All!$V4="P7",All!$AE4="RSS"),Ruler!F$28,IF(AND(All!$V4="P8",All!$AE4="RSS"),Ruler!F$29,IF(AND(All!$V4="P9",All!$AE4="RSS"),Ruler!F$30,0))))))))))))))))))))))))))) -> 2 | BN4: =IF(AND(All!$V4="P1",All!$AE4="RDP"),Ruler!G$6,IF(AND(All!$V4="P2",All!$AE4="RDP"),Ruler!G$7,IF(AND(All!$V4="P3",All!$AE4="RDP"),Ruler!G$8,IF(AND(All!$V4="P4",All!$AE4="RDP"),Ruler!G$9,IF(AND(All!$V4="P5",All!$AE4="RDP"),Ruler!G$10,IF(AND(All!$V4="P6",All!$AE4="RDP"),Ruler!G$11,IF(AND(All!$V4="P7",All!$AE4="RDP"),Ruler!G$12,IF(AND(All!$V4="P8",All!$AE4="RDP"),Ruler!G$13,IF(AND(All!$V4="P9",All!$AE4="RDP"),Ruler!G$14,IF(AND(All!$V4="P1",All!$AE4="RMS"),Ruler!G$6,IF(AND(All!$V4="P2",All!$AE4="RMS"),Ruler!G$15,IF(AND(All!$V4="P3",All!$AE4="RMS"),Ruler!G$16,IF(AND(All!$V4="P4",All!$AE4="RMS"),Ruler!G$17,IF(AND(All!$V4="P5",All!$AE4="RMS"),Ruler!G$18,IF(AND(All!$V4="P6",All!$AE4="RMS"),Ruler!G$19,IF(AND(All!$V4="P7",All!$AE4="RMS"),Ruler!G$20,IF(AND(All!$V4="P8",All!$AE4="RMS"),Ruler!G$21,IF(AND(All!$V4="P9",All!$AE4="RMS"),Ruler!G$22,IF(AND(All!$V4="P1",All!$AE4="RSS"),Ruler!G$6,IF(AND(All!$V4="P2",All!$AE4="RSS"),Ruler!G$23,IF(AND(All!$V4="P3",All!$AE4="RSS"),Ruler!G$24,IF(AND(All!$V4="P4",All!$AE4="RSS"),Ruler!G$25,IF(AND(All!$V4="P5",All!$AE4="RSS"),Ruler!G$26,IF(AND(All!$V4="P6",All!$AE4="RSS"),Ruler!G$27,IF(AND(All!$V4="P7",All!$AE4="RSS"),Ruler!G$28,IF(AND(All!$V4="P8",All!$AE4="RSS"),Ruler!G$29,IF(AND(All!$V4="P9",All!$AE4="RSS"),Ruler!G$30,0))))))))))))))))))))))))))) -> 1 | BO4: =IF(AND(All!$V4="P1",All!$AE4="RDP"),Ruler!H$6,IF(AND(All!$V4="P2",All!$AE4="RDP"),Ruler!H$7,IF(AND(All!$V4="P3",All!$AE4="RDP"),Ruler!H$8,IF(AND(All!$V4="P4",All!$AE4="RDP"),Ruler!H$9,IF(AND(All!$V4="P5",All!$AE4="RDP"),Ruler!H$10,IF(AND(All!$V4="P6",All!$AE4="RDP"),Ruler!H$11,IF(AND(All!$V4="P7",All!$AE4="RDP"),Ruler!H$12,IF(AND(All!$V4="P8",All!$AE4="RDP"),Ruler!H$13,IF(AND(All!$V4="P9",All!$AE4="RDP"),Ruler!H$14,IF(AND(All!$V4="P1",All!$AE4="RMS"),Ruler!H$6,IF(AND(All!$V4="P2",All!$AE4="RMS"),Ruler!H$15,IF(AND(All!$V4="P3",All!$AE4="RMS"),Ruler!H$16,IF(AND(All!$V4="P4",All!$AE4="RMS"),Ruler!H$17,IF(AND(All!$V4="P5",All!$AE4="RMS"),Ruler!H$18,IF(AND(All!$V4="P6",All!$AE4="RMS"),Ruler!H$19,IF(AND(All!$V4="P7",All!$AE4="RMS"),Ruler!H$20,IF(AND(All!$V4="P8",All!$AE4="RMS"),Ruler!H$21,IF(AND(All!$V4="P9",All!$AE4="RMS"),Ruler!H$22,IF(AND(All!$V4="P1",All!$AE4="RSS"),Ruler!H$6,IF(AND(All!$V4="P2",All!$AE4="RSS"),Ruler!H$23,IF(AND(All!$V4="P3",All!$AE4="RSS"),Ruler!H$24,IF(AND(All!$V4="P4",All!$AE4="RSS"),Ruler!H$25,IF(AND(All!$V4="P5",All!$AE4="RSS"),Ruler!H$26,IF(AND(All!$V4="P6",All!$AE4="RSS"),Ruler!H$27,IF(AND(All!$V4="P7",All!$AE4="RSS"),Ruler!H$28,IF(AND(All!$V4="P8",All!$AE4="RSS"),Ruler!H$29,IF(AND(All!$V4="P9",All!$AE4="RSS"),Ruler!H$30,0))))))))))))))))))))))))))) -> 2 | BP4: =IF(AND(All!$V4="P1",All!$AE4="RDP"),Ruler!I$6,IF(AND(All!$V4="P2",All!$AE4="RDP"),Ruler!I$7,IF(AND(All!$V4="P3",All!$AE4="RDP"),Ruler!I$8,IF(AND(All!$V4="P4",All!$AE4="RDP"),Ruler!I$9,IF(AND(All!$V4="P5",All!$AE4="RDP"),Ruler!I$10,IF(AND(All!$V4="P6",All!$AE4="RDP"),Ruler!I$11,IF(AND(All!$V4="P7",All!$AE4="RDP"),Ruler!I$12,IF(AND(All!$V4="P8",All!$AE4="RDP"),Ruler!I$13,IF(AND(All!$V4="P9",All!$AE4="RDP"),Ruler!I$14,IF(AND(All!$V4="P1",All!$AE4="RMS"),Ruler!I$6,IF(AND(All!$V4="P2",All!$AE4="RMS"),Ruler!I$15,IF(AND(All!$V4="P3",All!$AE4="RMS"),Ruler!I$16,IF(AND(All!$V4="P4",All!$AE4="RMS"),Ruler!I$17,IF(AND(All!$V4="P5",All!$AE4="RMS"),Ruler!I$18,IF(AND(All!$V4="P6",All!$AE4="RMS"),Ruler!I$19,IF(AND(All!$V4="P7",All!$AE4="RMS"),Ruler!I$20,IF(AND(All!$V4="P8",All!$AE4="RMS"),Ruler!I$21,IF(AND(All!$V4="P9",All!$AE4="RMS"),Ruler!I$22,IF(AND(All!$V4="P1",All!$AE4="RSS"),Ruler!I$6,IF(AND(All!$V4="P2",All!$AE4="RSS"),Ruler!I$23,IF(AND(All!$V4="P3",All!$AE4="RSS"),Ruler!I$24,IF(AND(All!$V4="P4",All!$AE4="RSS"),Ruler!I$25,IF(AND(All!$V4="P5",All!$AE4="RSS"),Ruler!I$26,IF(AND(All!$V4="P6",All!$AE4="RSS"),Ruler!I$27,IF(AND(All!$V4="P7",All!$AE4="RSS"),Ruler!I$28,IF(AND(All!$V4="P8",All!$AE4="RSS"),Ruler!I$29,IF(AND(All!$V4="P9",All!$AE4="RSS"),Ruler!I$30,0))))))))))))))))))))))))))) -> 2 | BQ4: =IF(AND(All!$V4="P1",All!$AE4="RDP"),Ruler!J$6,IF(AND(All!$V4="P2",All!$AE4="RDP"),Ruler!J$7,IF(AND(All!$V4="P3",All!$AE4="RDP"),Ruler!J$8,IF(AND(All!$V4="P4",All!$AE4="RDP"),Ruler!J$9,IF(AND(All!$V4="P5",All!$AE4="RDP"),Ruler!J$10,IF(AND(All!$V4="P6",All!$AE4="RDP"),Ruler!J$11,IF(AND(All!$V4="P7",All!$AE4="RDP"),Ruler!J$12,IF(AND(All!$V4="P8",All!$AE4="RDP"),Ruler!J$13,IF(AND(All!$V4="P9",All!$AE4="RDP"),Ruler!J$14,IF(AND(All!$V4="P1",All!$AE4="RMS"),Ruler!J$6,IF(AND(All!$V4="P2",All!$AE4="RMS"),Ruler!J$15,IF(AND(All!$V4="P3",All!$AE4="RMS"),Ruler!J$16,IF(AND(All!$V4="P4",All!$AE4="RMS"),Ruler!J$17,IF(AND(All!$V4="P5",All!$AE4="RMS"),Ruler!J$18,IF(AND(All!$V4="P6",All!$AE4="RMS"),Ruler!J$19,IF(AND(All!$V4="P7",All!$AE4="RMS"),Ruler!J$20,IF(AND(All!$V4="P8",All!$AE4="RMS"),Ruler!J$21,IF(AND(All!$V4="P9",All!$AE4="RMS"),Ruler!J$22,IF(AND(All!$V4="P1",All!$AE4="RSS"),Ruler!J$6,IF(AND(All!$V4="P2",All!$AE4="RSS"),Ruler!J$23,IF(AND(All!$V4="P3",All!$AE4="RSS"),Ruler!J$24,IF(AND(All!$V4="P4",All!$AE4="RSS"),Ruler!J$25,IF(AND(All!$V4="P5",All!$AE4="RSS"),Ruler!J$26,IF(AND(All!$V4="P6",All!$AE4="RSS"),Ruler!J$27,IF(AND(All!$V4="P7",All!$AE4="RSS"),Ruler!J$28,IF(AND(All!$V4="P8",All!$AE4="RSS"),Ruler!J$29,IF(AND(All!$V4="P9",All!$AE4="RSS"),Ruler!J$30,0))))))))))))))))))))))))))) -> 2 | BR4: =IF(AND(All!$V4="P1",All!$AE4="RDP"),Ruler!K$6,IF(AND(All!$V4="P2",All!$AE4="RDP"),Ruler!K$7,IF(AND(All!$V4="P3",All!$AE4="RDP"),Ruler!K$8,IF(AND(All!$V4="P4",All!$AE4="RDP"),Ruler!K$9,IF(AND(All!$V4="P5",All!$AE4="RDP"),Ruler!K$10,IF(AND(All!$V4="P6",All!$AE4="RDP"),Ruler!K$11,IF(AND(All!$V4="P7",All!$AE4="RDP"),Ruler!K$12,IF(AND(All!$V4="P8",All!$AE4="RDP"),Ruler!K$13,IF(AND(All!$V4="P9",All!$AE4="RDP"),Ruler!K$14,IF(AND(All!$V4="P1",All!$AE4="RMS"),Ruler!K$6,IF(AND(All!$V4="P2",All!$AE4="RMS"),Ruler!K$15,IF(AND(All!$V4="P3",All!$AE4="RMS"),Ruler!K$16,IF(AND(All!$V4="P4",All!$AE4="RMS"),Ruler!K$17,IF(AND(All!$V4="P5",All!$AE4="RMS"),Ruler!K$18,IF(AND(All!$V4="P6",All!$AE4="RMS"),Ruler!K$19,IF(AND(All!$V4="P7",All!$AE4="RMS"),Ruler!K$20,IF(AND(All!$V4="P8",All!$AE4="RMS"),Ruler!K$21,IF(AND(All!$V4="P9",All!$AE4="RMS"),Ruler!K$22,IF(AND(All!$V4="P1",All!$AE4="RSS"),Ruler!K$6,IF(AND(All!$V4="P2",All!$AE4="RSS"),Ruler!K$23,IF(AND(All!$V4="P3",All!$AE4="RSS"),Ruler!K$24,IF(AND(All!$V4="P4",All!$AE4="RSS"),Ruler!K$25,IF(AND(All!$V4="P5",All!$AE4="RSS"),Ruler!K$26,IF(AND(All!$V4="P6",All!$AE4="RSS"),Ruler!K$27,IF(AND(All!$V4="P7",All!$AE4="RSS"),Ruler!K$28,IF(AND(All!$V4="P8",All!$AE4="RSS"),Ruler!K$29,IF(AND(All!$V4="P9",All!$AE4="RSS"),Ruler!K$30,0))))))))))))))))))))))))))) -> 3 | BS4: =IF(AND(All!$V4="P1",All!$AE4="RDP"),Ruler!L$6,IF(AND(All!$V4="P2",All!$AE4="RDP"),Ruler!L$7,IF(AND(All!$V4="P3",All!$AE4="RDP"),Ruler!L$8,IF(AND(All!$V4="P4",All!$AE4="RDP"),Ruler!L$9,IF(AND(All!$V4="P5",All!$AE4="RDP"),Ruler!L$10,IF(AND(All!$V4="P6",All!$AE4="RDP"),Ruler!L$11,IF(AND(All!$V4="P7",All!$AE4="RDP"),Ruler!L$12,IF(AND(All!$V4="P8",All!$AE4="RDP"),Ruler!L$13,IF(AND(All!$V4="P9",All!$AE4="RDP"),Ruler!L$14,IF(AND(All!$V4="P1",All!$AE4="RMS"),Ruler!L$6,IF(AND(All!$V4="P2",All!$AE4="RMS"),Ruler!L$15,IF(AND(All!$V4="P3",All!$AE4="RMS"),Ruler!L$16,IF(AND(All!$V4="P4",All!$AE4="RMS"),Ruler!L$17,IF(AND(All!$V4="P5",All!$AE4="RMS"),Ruler!L$18,IF(AND(All!$V4="P6",All!$AE4="RMS"),Ruler!L$19,IF(AND(All!$V4="P7",All!$AE4="RMS"),Ruler!L$20,IF(AND(All!$V4="P8",All!$AE4="RMS"),Ruler!L$21,IF(AND(All!$V4="P9",All!$AE4="RMS"),Ruler!L$22,IF(AND(All!$V4="P1",All!$AE4="RSS"),Ruler!L$6,IF(AND(All!$V4="P2",All!$AE4="RSS"),Ruler!L$23,IF(AND(All!$V4="P3",All!$AE4="RSS"),Ruler!L$24,IF(AND(All!$V4="P4",All!$AE4="RSS"),Ruler!L$25,IF(AND(All!$V4="P5",All!$AE4="RSS"),Ruler!L$26,IF(AND(All!$V4="P6",All!$AE4="RSS"),Ruler!L$27,IF(AND(All!$V4="P7",All!$AE4="RSS"),Ruler!L$28,IF(AND(All!$V4="P8",All!$AE4="RSS"),Ruler!L$29,IF(AND(All!$V4="P9",All!$AE4="RSS"),Ruler!L$30,0))))))))))))))))))))))))))) -> 2 | ... CI4: =IF(AND(All!$V4="P1",All!$AE4="RDP"),Ruler!AB$6,IF(AND(All!$V4="P2",All!$AE4="RDP"),Ruler!AB$7,IF(AND(All!$V4="P3",All!$AE4="RDP"),Ruler!AB$8,IF(AND(All!$V4="P4",All!$AE4="RDP"),Ruler!AB$9,IF(AND(All!$V4="P5",All!$AE4="RDP"),Ruler!AB$10,IF(AND(All!$V4="P6",All!$AE4="RDP"),Ruler!AB$11,IF(AND(All!$V4="P7",All!$AE4="RDP"),Ruler!AB$12,IF(AND(All!$V4="P8",All!$AE4="RDP"),Ruler!AB$13,IF(AND(All!$V4="P9",All!$AE4="RDP"),Ruler!AB$14,IF(AND(All!$V4="P1",All!$AE4="RMS"),Ruler!AB$6,IF(AND(All!$V4="P2",All!$AE4="RMS"),Ruler!AB$15,IF(AND(All!$V4="P3",All!$AE4="RMS"),Ruler!AB$16,IF(AND(All!$V4="P4",All!$AE4="RMS"),Ruler!AB$17,IF(AND(All!$V4="P5",All!$AE4="RMS"),Ruler!AB$18,IF(AND(All!$V4="P6",All!$AE4="RMS"),Ruler!AB$19,IF(AND(All!$V4="P7",All!$AE4="RMS"),Ruler!AB$20,IF(AND(All!$V4="P8",All!$AE4="RMS"),Ruler!AB$21,IF(AND(All!$V4="P9",All!$AE4="RMS"),Ruler!AB$22,IF(AND(All!$V4="P1",All!$AE4="RSS"),Ruler!AB$6,IF(AND(All!$V4="P2",All!$AE4="RSS"),Ruler!AB$23,IF(AND(All!$V4="P3",All!$AE4="RSS"),Ruler!AB$24,IF(AND(All!$V4="P4",All!$AE4="RSS"),Ruler!AB$25,IF(AND(All!$V4="P5",All!$AE4="RSS"),Ruler!AB$26,IF(AND(All!$V4="P6",All!$AE4="RSS"),Ruler!AB$27,IF(AND(All!$V4="P7",All!$AE4="RSS"),Ruler!AB$28,IF(AND(All!$V4="P8",All!$AE4="RSS"),Ruler!AB$29,IF(AND(All!$V4="P9",All!$AE4="RSS"),Ruler!AB$30,0))))))))))))))))))))))))))) -> 0 | CJ4: =Table9[[#This Row],[R-B1]]-Table9[[#This Row],[B1]] -> 0 | CK4: =Table9[[#This Row],[R-B2]]-Table9[[#This Row],[B2]] -> 1 | CL4: =Table9[[#This Row],[R-B3]]-Table9[[#This Row],[B3]] -> 0 | CM4: =Table9[[#This Row],[R-B4]]-Table9[[#This Row],[B4]] -> 0 | CN4: =Table9[[#This Row],[R-B5]]-Table9[[#This Row],[B5]] -> 0 | CO4: =Table9[[#This Row],[R-B6]]-Table9[[#This Row],[B6]] -> 0 | CP4: =Table9[[#This Row],[R-B7]]-Table9[[#This Row],[B7]] -> 1 | CQ4: =Table9[[#This Row],[R-B8]]-Table9[[#This Row],[B8]] -> 0 | CR4: =Table9[[#This Row],[R-B9]]-Table9[[#This Row],[B9]] -> 1 | CS4: =Table9[[#This Row],[R-B10]]-Table9[[#This Row],[B10]] -> 1 | CT4: =Table9[[#This Row],[R-B11]]-Table9[[#This Row],[B11]] -> 1 | CU4: =Table9[[#This Row],[R-B12]]-Table9[[#This Row],[B12]] -> 1 | CV4: =Table9[[#This Row],[R-K1]]-Table9[[#This Row],[K1]] -> 0 | CW4: =Table9[[#This Row],[R-K2]]-Table9[[#This Row],[K2]] -> 1 | CX4: =Table9[[#This Row],[R-K3]]-Table9[[#This Row],[K3]] -> 1 | CY4: =Table9[[#This Row],[R-K4]]-Table9[[#This Row],[K4]] -> 0 | CZ4: =Table9[[#This Row],[R-K5]]-Table9[[#This Row],[K5]] -> 1 | DA4: =Table9[[#This Row],[R-P1]]-Table9[[#This Row],[P1]] -> 0 | DB4: =Table9[[#This Row],[R-P2]]-Table9[[#This Row],[P2]] -> -1 | DC4: =Table9[[#This Row],[R-P3]]-Table9[[#This Row],[P3]] -> -1 | DD4: =Table9[[#This Row],[R-P4]]-Table9[[#This Row],[P4]] -> -1 | DE4: =Table9[[#This Row],[R-P5]]-Table9[[#This Row],[P5]] -> 1 | DF4: =Table9[[#This Row],[R-E1]]-Table9[[#This Row],[E1]] -> 0 | DG4: =Table9[[#This Row],[R-E2]]-Table9[[#This Row],[E2]] -> 0 | DH4: =COUNTIF(Table9[[#This Row],[G-B1]:[G-B12]],"<=0")/12*100 -> 50 | DI4: =COUNTIF(Table9[[#This Row],[G-K1]:[G-K5]],"<=0")/5*100 -> 40 | DJ4: =COUNTIF(Table9[[#This Row],[G-P1]:[G-P5]],"<=0")/5*100 -> 80 | DK4: =COUNTIF(Table9[[#This Row],[G-E1]:[G-E2]],"<=0")/2*100 -> 100 | DL4: =IF(AE4="RDP",(COUNTIF(Table9[[#This Row],[G-B3]],"<=0")+COUNTIF(Table9[[#This Row],[G-B4]],"<=0")+COUNTIF(Table9[[#This Row],[G-B7]],"<=0")+COUNTIF(Table9[[#This Row],[G-B11]],"<=0")+COUNTIF(Table9[[#This Row],[G-K2]],"<=0"))/5*100,IF(AE4="RMS",(COUNTIF(Table9[[#This Row],[G-B4]],"<=0")+COUNTIF(Table9[[#This Row],[G-B5]],"<=0")+COUNTIF(Table9[[#This Row],[G-B10]],"<=0")+COUNTIF(Table9[[#This Row],[G-B12]],"<=0")+COUNTIF(Table9[[#This Row],[G-K2]],"<=0"))/5*100,IF(AE4="RSS",(COUNTIF(Table9[[#This Row],[G-B1]],"<=0")+COUNTIF(Table9[[#This Row],[G-B2]],"<=0")+COUNTIF(Table9[[#This Row],[G-B6]],"<=0")+COUNTIF(Table9[[#This Row],[G-B11]],"<=0")+COUNTIF(Table9[[#This Row],[G-B12]],"<=0"))/5*100,0))) -> 40 | DM4: 8 | DN4: 0 | DO4: 60 | DP4: 0 | DQ4: 0 | DR4: 0 | DS4: 0 | DT4: 60 | DU4: 0 | DV4: 0 | DW4: 0 | DX4: 0 | DY4: 0 | DZ4: 0 | EA4: 0 | EE4: UPE map to RDP ruler
B5: 2 | C5: Yes | D5: 46146 | E5: Abdul Hakim bin Basri | F5: 1028534 | G5: =($T$1-H5)/365 -> 35.82639 | H5: 33239 | I5: M | J5: Malaysia | K5: IRQ | L5: PE | M5: RMS | N5: Gharaf | O5: Snr RE | P5: hakim.basri@petronas.com.my | Q5: Permanent | S5: 42095 | T5: =YEARFRAC(S5,$T$1) -> 11.552778 | U5: =Table9[[#This Row],[Years in PET]] -> 11.552778 | V5: P4 | X5: =($T$1-Table9[[#This Row],[Date of Appointment to Current Grade]])/365 -> 1.5551569 | Y5: 45748 | Z5: Iraq | AB5: 0.6 | AC5: UPE | AE5: RSS | AF5: High | AH5: ✅ IOR/EOR (Angsi EORC,Bokor IWAG), ✅ Dynamic modeling+ HM, ✅ FDP/FFR brown and greenfield, ✅ Deepwater development concept, ✅ surveillance&optmization | AI5: TPCP self assesssmnet, identify gap and try to address through current job | AJ5: EOR, Modeling | AK5: SMA passed. Not yet decided his path | AL5: Undecided | AM5: Win-win arrangement, | AN5: 3 | AO5: 3 | AP5: 3 | AQ5: 1 | AR5: 2 | AS5: 2 | AT5: 2 | AU5: 3 | AV5: 2 | AW5: 2 | AX5: 2 | AY5: 2 | AZ5: 2 | BA5: 2 | BB5: 1 | BC5: 1 | BD5: 1 | BE5: 1 | BF5: 1 | BG5: 1 | BH5: 1 | BI5: 1 | BJ5: 1 | BK5: 1 | BL5: =IF(AND(All!$V5="P1",All!$AE5="RDP"),Ruler!E$6,IF(AND(All!$V5="P2",All!$AE5="RDP"),Ruler!E$7,IF(AND(All!$V5="P3",All!$AE5="RDP"),Ruler!E$8,IF(AND(All!$V5="P4",All!$AE5="RDP"),Ruler!E$9,IF(AND(All!$V5="P5",All!$AE5="RDP"),Ruler!E$10,IF(AND(All!$V5="P6",All!$AE5="RDP"),Ruler!E$11,IF(AND(All!$V5="P7",All!$AE5="RDP"),Ruler!E$12,IF(AND(All!$V5="P8",All!$AE5="RDP"),Ruler!E$13,IF(AND(All!$V5="P9",All!$AE5="RDP"),Ruler!E$14,IF(AND(All!$V5="P1",All!$AE5="RMS"),Ruler!E$6,IF(AND(All!$V5="P2",All!$AE5="RMS"),Ruler!E$15,IF(AND(All!$V5="P3",All!$AE5="RMS"),Ruler!E$16,IF(AND(All!$V5="P4",All!$AE5="RMS"),Ruler!E$17,IF(AND(All!$V5="P5",All!$AE5="RMS"),Ruler!E$18,IF(AND(All!$V5="P6",All!$AE5="RMS"),Ruler!E$19,IF(AND(All!$V5="P7",All!$AE5="RMS"),Ruler!E$20,IF(AND(All!$V5="P8",All!$AE5="RMS"),Ruler!E$21,IF(AND(All!$V5="P9",All!$AE5="RMS"),Ruler!E$22,IF(AND(All!$V5="P1",All!$AE5="RSS"),Ruler!E$6,IF(AND(All!$V5="P2",All!$AE5="RSS"),Ruler!E$23,IF(AND(All!$V5="P3",All!$AE5="RSS"),Ruler!E$24,IF(AND(All!$V5="P4",All!$AE5="RSS"),Ruler!E$25,IF(AND(All!$V5="P5",All!$AE5="RSS"),Ruler!E$26,IF(AND(All!$V5="P6",All!$AE5="RSS"),Ruler!E$27,IF(AND(All!$V5="P7",All!$AE5="RSS"),Ruler!E$28,IF(AND(All!$V5="P8",All!$AE5="RSS"),Ruler!E$29,IF(AND(All!$V5="P9",All!$AE5="RSS"),Ruler!E$30,0))))))))))))))))))))))))))) -> 3 | BM5: =IF(AND(All!$V5="P1",All!$AE5="RDP"),Ruler!F$6,IF(AND(All!$V5="P2",All!$AE5="RDP"),Ruler!F$7,IF(AND(All!$V5="P3",All!$AE5="RDP"),Ruler!F$8,IF(AND(All!$V5="P4",All!$AE5="RDP"),Ruler!F$9,IF(AND(All!$V5="P5",All!$AE5="RDP"),Ruler!F$10,IF(AND(All!$V5="P6",All!$AE5="RDP"),Ruler!F$11,IF(AND(All!$V5="P7",All!$AE5="RDP"),Ruler!F$12,IF(AND(All!$V5="P8",All!$AE5="RDP"),Ruler!F$13,IF(AND(All!$V5="P9",All!$AE5="RDP"),Ruler!F$14,IF(AND(All!$V5="P1",All!$AE5="RMS"),Ruler!F$6,IF(AND(All!$V5="P2",All!$AE5="RMS"),Ruler!F$15,IF(AND(All!$V5="P3",All!$AE5="RMS"),Ruler!F$16,IF(AND(All!$V5="P4",All!$AE5="RMS"),Ruler!F$17,IF(AND(All!$V5="P5",All!$AE5="RMS"),Ruler!F$18,IF(AND(All!$V5="P6",All!$AE5="RMS"),Ruler!F$19,IF(AND(All!$V5="P7",All!$AE5="RMS"),Ruler!F$20,IF(AND(All!$V5="P8",All!$AE5="RMS"),Ruler!F$21,IF(AND(All!$V5="P9",All!$AE5="RMS"),Ruler!F$22,IF(AND(All!$V5="P1",All!$AE5="RSS"),Ruler!F$6,IF(AND(All!$V5="P2",All!$AE5="RSS"),Ruler!F$23,IF(AND(All!$V5="P3",All!$AE5="RSS"),Ruler!F$24,IF(AND(All!$V5="P4",All!$AE5="RSS"),Ruler!F$25,IF(AND(All!$V5="P5",All!$AE5="RSS"),Ruler!F$26,IF(AND(All!$V5="P6",All!$AE5="RSS"),Ruler!F$27,IF(AND(All!$V5="P7",All!$AE5="RSS"),Ruler!F$28,IF(AND(All!$V5="P8",All!$AE5="RSS"),Ruler!F$29,IF(AND(All!$V5="P9",All!$AE5="RSS"),Ruler!F$30,0))))))))))))))))))))))))))) -> 3 | BN5: =IF(AND(All!$V5="P1",All!$AE5="RDP"),Ruler!G$6,IF(AND(All!$V5="P2",All!$AE5="RDP"),Ruler!G$7,IF(AND(All!$V5="P3",All!$AE5="RDP"),Ruler!G$8,IF(AND(All!$V5="P4",All!$AE5="RDP"),Ruler!G$9,IF(AND(All!$V5="P5",All!$AE5="RDP"),Ruler!G$10,IF(AND(All!$V5="P6",All!$AE5="RDP"),Ruler!G$11,IF(AND(All!$V5="P7",All!$AE5="RDP"),Ruler!G$12,IF(AND(All!$V5="P8",All!$AE5="RDP"),Ruler!G$13,IF(AND(All!$V5="P9",All!$AE5="RDP"),Ruler!G$14,IF(AND(All!$V5="P1",All!$AE5="RMS"),Ruler!G$6,IF(AND(All!$V5="P2",All!$AE5="RMS"),Ruler!G$15,IF(AND(All!$V5="P3",All!$AE5="RMS"),Ruler!G$16,IF(AND(All!$V5="P4",All!$AE5="RMS"),Ruler!G$17,IF(AND(All!$V5="P5",All!$AE5="RMS"),Ruler!G$18,IF(AND(All!$V5="P6",All!$AE5="RMS"),Ruler!G$19,IF(AND(All!$V5="P7",All!$AE5="RMS"),Ruler!G$20,IF(AND(All!$V5="P8",All!$AE5="RMS"),Ruler!G$21,IF(AND(All!$V5="P9",All!$AE5="RMS"),Ruler!G$22,IF(AND(All!$V5="P1",All!$AE5="RSS"),Ruler!G$6,IF(AND(All!$V5="P2",All!$AE5="RSS"),Ruler!G$23,IF(AND(All!$V5="P3",All!$AE5="RSS"),Ruler!G$24,IF(AND(All!$V5="P4",All!$AE5="RSS"),Ruler!G$25,IF(AND(All!$V5="P5",All!$AE5="RSS"),Ruler!G$26,IF(AND(All!$V5="P6",All!$AE5="RSS"),Ruler!G$27,IF(AND(All!$V5="P7",All!$AE5="RSS"),Ruler!G$28,IF(AND(All!$V5="P8",All!$AE5="RSS"),Ruler!G$29,IF(AND(All!$V5="P9",All!$AE5="RSS"),Ruler!G$30,0))))))))))))))))))))))))))) -> 2 | BO5: =IF(AND(All!$V5="P1",All!$AE5="RDP"),Ruler!H$6,IF(AND(All!$V5="P2",All!$AE5="RDP"),Ruler!H$7,IF(AND(All!$V5="P3",All!$AE5="RDP"),Ruler!H$8,IF(AND(All!$V5="P4",All!$AE5="RDP"),Ruler!H$9,IF(AND(All!$V5="P5",All!$AE5="RDP"),Ruler!H$10,IF(AND(All!$V5="P6",All!$AE5="RDP"),Ruler!H$11,IF(AND(All!$V5="P7",All!$AE5="RDP"),Ruler!H$12,IF(AND(All!$V5="P8",All!$AE5="RDP"),Ruler!H$13,IF(AND(All!$V5="P9",All!$AE5="RDP"),Ruler!H$14,IF(AND(All!$V5="P1",All!$AE5="RMS"),Ruler!H$6,IF(AND(All!$V5="P2",All!$AE5="RMS"),Ruler!H$15,IF(AND(All!$V5="P3",All!$AE5="RMS"),Ruler!H$16,IF(AND(All!$V5="P4",All!$AE5="RMS"),Ruler!H$17,IF(AND(All!$V5="P5",All!$AE5="RMS"),Ruler!H$18,IF(AND(All!$V5="P6",All!$AE5="RMS"),Ruler!H$19,IF(AND(All!$V5="P7",All!$AE5="RMS"),Ruler!H$20,IF(AND(All!$V5="P8",All!$AE5="RMS"),Ruler!H$21,IF(AND(All!$V5="P9",All!$AE5="RMS"),Ruler!H$22,IF(AND(All!$V5="P1",All!$AE5="RSS"),Ruler!H$6,IF(AND(All!$V5="P2",All!$AE5="RSS"),Ruler!H$23,IF(AND(All!$V5="P3",All!$AE5="RSS"),Ruler!H$24,IF(AND(All!$V5="P4",All!$AE5="RSS"),Ruler!H$25,IF(AND(All!$V5="P5",All!$AE5="RSS"),Ruler!H$26,IF(AND(All!$V5="P6",All!$AE5="RSS"),Ruler!H$27,IF(AND(All!$V5="P7",All!$AE5="RSS"),Ruler!H$28,IF(AND(All!$V5="P8",All!$AE5="RSS"),Ruler!H$29,IF(AND(All!$V5="P9",All!$AE5="RSS"),Ruler!H$30,0))))))))))))))))))))))))))) -> 3 | BP5: =IF(AND(All!$V5="P1",All!$AE5="RDP"),Ruler!I$6,IF(AND(All!$V5="P2",All!$AE5="RDP"),Ruler!I$7,IF(AND(All!$V5="P3",All!$AE5="RDP"),Ruler!I$8,IF(AND(All!$V5="P4",All!$AE5="RDP"),Ruler!I$9,IF(AND(All!$V5="P5",All!$AE5="RDP"),Ruler!I$10,IF(AND(All!$V5="P6",All!$AE5="RDP"),Ruler!I$11,IF(AND(All!$V5="P7",All!$AE5="RDP"),Ruler!I$12,IF(AND(All!$V5="P8",All!$AE5="RDP"),Ruler!I$13,IF(AND(All!$V5="P9",All!$AE5="RDP"),Ruler!I$14,IF(AND(All!$V5="P1",All!$AE5="RMS"),Ruler!I$6,IF(AND(All!$V5="P2",All!$AE5="RMS"),Ruler!I$15,IF(AND(All!$V5="P3",All!$AE5="RMS"),Ruler!I$16,IF(AND(All!$V5="P4",All!$AE5="RMS"),Ruler!I$17,IF(AND(All!$V5="P5",All!$AE5="RMS"),Ruler!I$18,IF(AND(All!$V5="P6",All!$AE5="RMS"),Ruler!I$19,IF(AND(All!$V5="P7",All!$AE5="RMS"),Ruler!I$20,IF(AND(All!$V5="P8",All!$AE5="RMS"),Ruler!I$21,IF(AND(All!$V5="P9",All!$AE5="RMS"),Ruler!I$22,IF(AND(All!$V5="P1",All!$AE5="RSS"),Ruler!I$6,IF(AND(All!$V5="P2",All!$AE5="RSS"),Ruler!I$23,IF(AND(All!$V5="P3",All!$AE5="RSS"),Ruler!I$24,IF(AND(All!$V5="P4",All!$AE5="RSS"),Ruler!I$25,IF(AND(All!$V5="P5",All!$AE5="RSS"),Ruler!I$26,IF(AND(All!$V5="P6",All!$AE5="RSS"),Ruler!I$27,IF(AND(All!$V5="P7",All!$AE5="RSS"),Ruler!I$28,IF(AND(All!$V5="P8",All!$AE5="RSS"),Ruler!I$29,IF(AND(All!$V5="P9",All!$AE5="RSS"),Ruler!I$30,0))))))))))))))))))))))))))) -> 3 | BQ5: =IF(AND(All!$V5="P1",All!$AE5="RDP"),Ruler!J$6,IF(AND(All!$V5="P2",All!$AE5="RDP"),Ruler!J$7,IF(AND(All!$V5="P3",All!$AE5="RDP"),Ruler!J$8,IF(AND(All!$V5="P4",All!$AE5="RDP"),Ruler!J$9,IF(AND(All!$V5="P5",All!$AE5="RDP"),Ruler!J$10,IF(AND(All!$V5="P6",All!$AE5="RDP"),Ruler!J$11,IF(AND(All!$V5="P7",All!$AE5="RDP"),Ruler!J$12,IF(AND(All!$V5="P8",All!$AE5="RDP"),Ruler!J$13,IF(AND(All!$V5="P9",All!$AE5="RDP"),Ruler!J$14,IF(AND(All!$V5="P1",All!$AE5="RMS"),Ruler!J$6,IF(AND(All!$V5="P2",All!$AE5="RMS"),Ruler!J$15,IF(AND(All!$V5="P3",All!$AE5="RMS"),Ruler!J$16,IF(AND(All!$V5="P4",All!$AE5="RMS"),Ruler!J$17,IF(AND(All!$V5="P5",All!$AE5="RMS"),Ruler!J$18,IF(AND(All!$V5="P6",All!$AE5="RMS"),Ruler!J$19,IF(AND(All!$V5="P7",All!$AE5="RMS"),Ruler!J$20,IF(AND(All!$V5="P8",All!$AE5="RMS"),Ruler!J$21,IF(AND(All!$V5="P9",All!$AE5="RMS"),Ruler!J$22,IF(AND(All!$V5="P1",All!$AE5="RSS"),Ruler!J$6,IF(AND(All!$V5="P2",All!$AE5="RSS"),Ruler!J$23,IF(AND(All!$V5="P3",All!$AE5="RSS"),Ruler!J$24,IF(AND(All!$V5="P4",All!$AE5="RSS"),Ruler!J$25,IF(AND(All!$V5="P5",All!$AE5="RSS"),Ruler!J$26,IF(AND(All!$V5="P6",All!$AE5="RSS"),Ruler!J$27,IF(AND(All!$V5="P7",All!$AE5="RSS"),Ruler!J$28,IF(AND(All!$V5="P8",All!$AE5="RSS"),Ruler!J$29,IF(AND(All!$V5="P9",All!$AE5="RSS"),Ruler!J$30,0))))))))))))))))))))))))))) -> 3 | BR5: =IF(AND(All!$V5="P1",All!$AE5="RDP"),Ruler!K$6,IF(AND(All!$V5="P2",All!$AE5="RDP"),Ruler!K$7,IF(AND(All!$V5="P3",All!$AE5="RDP"),Ruler!K$8,IF(AND(All!$V5="P4",All!$AE5="RDP"),Ruler!K$9,IF(AND(All!$V5="P5",All!$AE5="RDP"),Ruler!K$10,IF(AND(All!$V5="P6",All!$AE5="RDP"),Ruler!K$11,IF(AND(All!$V5="P7",All!$AE5="RDP"),Ruler!K$12,IF(AND(All!$V5="P8",All!$AE5="RDP"),Ruler!K$13,IF(AND(All!$V5="P9",All!$AE5="RDP"),Ruler!K$14,IF(AND(All!$V5="P1",All!$AE5="RMS"),Ruler!K$6,IF(AND(All!$V5="P2",All!$AE5="RMS"),Ruler!K$15,IF(AND(All!$V5="P3",All!$AE5="RMS"),Ruler!K$16,IF(AND(All!$V5="P4",All!$AE5="RMS"),Ruler!K$17,IF(AND(All!$V5="P5",All!$AE5="RMS"),Ruler!K$18,IF(AND(All!$V5="P6",All!$AE5="RMS"),Ruler!K$19,IF(AND(All!$V5="P7",All!$AE5="RMS"),Ruler!K$20,IF(AND(All!$V5="P8",All!$AE5="RMS"),Ruler!K$21,IF(AND(All!$V5="P9",All!$AE5="RMS"),Ruler!K$22,IF(AND(All!$V5="P1",All!$AE5="RSS"),Ruler!K$6,IF(AND(All!$V5="P2",All!$AE5="RSS"),Ruler!K$23,IF(AND(All!$V5="P3",All!$AE5="RSS"),Ruler!K$24,IF(AND(All!$V5="P4",All!$AE5="RSS"),Ruler!K$25,IF(AND(All!$V5="P5",All!$AE5="RSS"),Ruler!K$26,IF(AND(All!$V5="P6",All!$AE5="RSS"),Ruler!K$27,IF(AND(All!$V5="P7",All!$AE5="RSS"),Ruler!K$28,IF(AND(All!$V5="P8",All!$AE5="RSS"),Ruler!K$29,IF(AND(All!$V5="P9",All!$AE5="RSS"),Ruler!K$30,0))))))))))))))))))))))))))) -> 3 | BS5: =IF(AND(All!$V5="P1",All!$AE5="RDP"),Ruler!L$6,IF(AND(All!$V5="P2",All!$AE5="RDP"),Ruler!L$7,IF(AND(All!$V5="P3",All!$AE5="RDP"),Ruler!L$8,IF(AND(All!$V5="P4",All!$AE5="RDP"),Ruler!L$9,IF(AND(All!$V5="P5",All!$AE5="RDP"),Ruler!L$10,IF(AND(All!$V5="P6",All!$AE5="RDP"),Ruler!L$11,IF(AND(All!$V5="P7",All!$AE5="RDP"),Ruler!L$12,IF(AND(All!$V5="P8",All!$AE5="RDP"),Ruler!L$13,IF(AND(All!$V5="P9",All!$AE5="RDP"),Ruler!L$14,IF(AND(All!$V5="P1",All!$AE5="RMS"),Ruler!L$6,IF(AND(All!$V5="P2",All!$AE5="RMS"),Ruler!L$15,IF(AND(All!$V5="P3",All!$AE5="RMS"),Ruler!L$16,IF(AND(All!$V5="P4",All!$AE5="RMS"),Ruler!L$17,IF(AND(All!$V5="P5",All!$AE5="RMS"),Ruler!L$18,IF(AND(All!$V5="P6",All!$AE5="RMS"),Ruler!L$19,IF(AND(All!$V5="P7",All!$AE5="RMS"),Ruler!L$20,IF(AND(All!$V5="P8",All!$AE5="RMS"),Ruler!L$21,IF(AND(All!$V5="P9",All!$AE5="RMS"),Ruler!L$22,IF(AND(All!$V5="P1",All!$AE5="RSS"),Ruler!L$6,IF(AND(All!$V5="P2",All!$AE5="RSS"),Ruler!L$23,IF(AND(All!$V5="P3",All!$AE5="RSS"),Ruler!L$24,IF(AND(All!$V5="P4",All!$AE5="RSS"),Ruler!L$25,IF(AND(All!$V5="P5",All!$AE5="RSS"),Ruler!L$26,IF(AND(All!$V5="P6",All!$AE5="RSS"),Ruler!L$27,IF(AND(All!$V5="P7",All!$AE5="RSS"),Ruler!L$28,IF(AND(All!$V5="P8",All!$AE5="RSS"),Ruler!L$29,IF(AND(All!$V5="P9",All!$AE5="RSS"),Ruler!L$30,0))))))))))))))))))))))))))) -> 2 | ... CI5: =IF(AND(All!$V5="P1",All!$AE5="RDP"),Ruler!AB$6,IF(AND(All!$V5="P2",All!$AE5="RDP"),Ruler!AB$7,IF(AND(All!$V5="P3",All!$AE5="RDP"),Ruler!AB$8,IF(AND(All!$V5="P4",All!$AE5="RDP"),Ruler!AB$9,IF(AND(All!$V5="P5",All!$AE5="RDP"),Ruler!AB$10,IF(AND(All!$V5="P6",All!$AE5="RDP"),Ruler!AB$11,IF(AND(All!$V5="P7",All!$AE5="RDP"),Ruler!AB$12,IF(AND(All!$V5="P8",All!$AE5="RDP"),Ruler!AB$13,IF(AND(All!$V5="P9",All!$AE5="RDP"),Ruler!AB$14,IF(AND(All!$V5="P1",All!$AE5="RMS"),Ruler!AB$6,IF(AND(All!$V5="P2",All!$AE5="RMS"),Ruler!AB$15,IF(AND(All!$V5="P3",All!$AE5="RMS"),Ruler!AB$16,IF(AND(All!$V5="P4",All!$AE5="RMS"),Ruler!AB$17,IF(AND(All!$V5="P5",All!$AE5="RMS"),Ruler!AB$18,IF(AND(All!$V5="P6",All!$AE5="RMS"),Ruler!AB$19,IF(AND(All!$V5="P7",All!$AE5="RMS"),Ruler!AB$20,IF(AND(All!$V5="P8",All!$AE5="RMS"),Ruler!AB$21,IF(AND(All!$V5="P9",All!$AE5="RMS"),Ruler!AB$22,IF(AND(All!$V5="P1",All!$AE5="RSS"),Ruler!AB$6,IF(AND(All!$V5="P2",All!$AE5="RSS"),Ruler!AB$23,IF(AND(All!$V5="P3",All!$AE5="RSS"),Ruler!AB$24,IF(AND(All!$V5="P4",All!$AE5="RSS"),Ruler!AB$25,IF(AND(All!$V5="P5",All!$AE5="RSS"),Ruler!AB$26,IF(AND(All!$V5="P6",All!$AE5="RSS"),Ruler!AB$27,IF(AND(All!$V5="P7",All!$AE5="RSS"),Ruler!AB$28,IF(AND(All!$V5="P8",All!$AE5="RSS"),Ruler!AB$29,IF(AND(All!$V5="P9",All!$AE5="RSS"),Ruler!AB$30,0))))))))))))))))))))))))))) -> 1 | CJ5: =Table9[[#This Row],[R-B1]]-Table9[[#This Row],[B1]] -> 0 | CK5: =Table9[[#This Row],[R-B2]]-Table9[[#This Row],[B2]] -> 0 | CL5: =Table9[[#This Row],[R-B3]]-Table9[[#This Row],[B3]] -> -1 | CM5: =Table9[[#This Row],[R-B4]]-Table9[[#This Row],[B4]] -> 2 | CN5: =Table9[[#This Row],[R-B5]]-Table9[[#This Row],[B5]] -> 1 | CO5: =Table9[[#This Row],[R-B6]]-Table9[[#This Row],[B6]] -> 1 | CP5: =Table9[[#This Row],[R-B7]]-Table9[[#This Row],[B7]] -> 1 | CQ5: =Table9[[#This Row],[R-B8]]-Table9[[#This Row],[B8]] -> -1 | CR5: =Table9[[#This Row],[R-B9]]-Table9[[#This Row],[B9]] -> 1 | CS5: =Table9[[#This Row],[R-B10]]-Table9[[#This Row],[B10]] -> -1 | CT5: =Table9[[#This Row],[R-B11]]-Table9[[#This Row],[B11]] -> 1 | CU5: =Table9[[#This Row],[R-B12]]-Table9[[#This Row],[B12]] -> 0 | CV5: =Table9[[#This Row],[R-K1]]-Table9[[#This Row],[K1]] -> 1 | CW5: =Table9[[#This Row],[R-K2]]-Table9[[#This Row],[K2]] -> 0 | CX5: =Table9[[#This Row],[R-K3]]-Table9[[#This Row],[K3]] -> 1 | CY5: =Table9[[#This Row],[R-K4]]-Table9[[#This Row],[K4]] -> 1 | CZ5: =Table9[[#This Row],[R-K5]]-Table9[[#This Row],[K5]] -> 1 | DA5: =Table9[[#This Row],[R-P1]]-Table9[[#This Row],[P1]] -> 1 | DB5: =Table9[[#This Row],[R-P2]]-Table9[[#This Row],[P2]] -> 1 | DC5: =Table9[[#This Row],[R-P3]]-Table9[[#This Row],[P3]] -> 1 | DD5: =Table9[[#This Row],[R-P4]]-Table9[[#This Row],[P4]] -> 0 | DE5: =Table9[[#This Row],[R-P5]]-Table9[[#This Row],[P5]] -> 1 | DF5: =Table9[[#This Row],[R-E1]]-Table9[[#This Row],[E1]] -> 0 | DG5: =Table9[[#This Row],[R-E2]]-Table9[[#This Row],[E2]] -> 0 | DH5: =COUNTIF(Table9[[#This Row],[G-B1]:[G-B12]],"<=0")/12*100 -> 50 | DI5: =COUNTIF(Table9[[#This Row],[G-K1]:[G-K5]],"<=0")/5*100 -> 20 | DJ5: =COUNTIF(Table9[[#This Row],[G-P1]:[G-P5]],"<=0")/5*100 -> 20 | DK5: =COUNTIF(Table9[[#This Row],[G-E1]:[G-E2]],"<=0")/2*100 -> 100 | DL5: =IF(AE5="RDP",(COUNTIF(Table9[[#This Row],[G-B3]],"<=0")+COUNTIF(Table9[[#This Row],[G-B4]],"<=0")+COUNTIF(Table9[[#This Row],[G-B7]],"<=0")+COUNTIF(Table9[[#This Row],[G-B11]],"<=0")+COUNTIF(Table9[[#This Row],[G-K2]],"<=0"))/5*100,IF(AE5="RMS",(COUNTIF(Table9[[#This Row],[G-B4]],"<=0")+COUNTIF(Table9[[#This Row],[G-B5]],"<=0")+COUNTIF(Table9[[#This Row],[G-B10]],"<=0")+COUNTIF(Table9[[#This Row],[G-B12]],"<=0")+COUNTIF(Table9[[#This Row],[G-K2]],"<=0"))/5*100,IF(AE5="RSS",(COUNTIF(Table9[[#This Row],[G-B1]],"<=0")+COUNTIF(Table9[[#This Row],[G-B2]],"<=0")+COUNTIF(Table9[[#This Row],[G-B6]],"<=0")+COUNTIF(Table9[[#This Row],[G-B11]],"<=0")+COUNTIF(Table9[[#This Row],[G-B12]],"<=0"))/5*100,0))) -> 60 | DM5: 50 | DN5: 20 | DO5: 20 | DP5: 100 | DQ5: 60 | DR5: 25 | DS5: 0 | DT5: 0 | DU5: 0 | DV5: 0 | DW5: 25 | DX5: 0 | DY5: 0 | DZ5: 0 | EA5: 0 | EE5: UPE map to RSS ruler
B6: 3 | C6: Not required | E6: Adi Krishna | G6: =($T$1-H6)/365 -> 36.82639 | H6: 32874 | I6: M | J6: Indonesia | K6: PCINO | L6: PE | M6: JVM | O6: Executive | P6: adi.krishna@petronas.com | Q6: CDH | X6: =($T$1-Table9[[#This Row],[Date of Appointment to Current Grade]])/365 -> 126.89214 | Z6: Indonesia | BL6: =IF(AND(All!$V6="P1",All!$AE6="RDP"),Ruler!E$6,IF(AND(All!$V6="P2",All!$AE6="RDP"),Ruler!E$7,IF(AND(All!$V6="P3",All!$AE6="RDP"),Ruler!E$8,IF(AND(All!$V6="P4",All!$AE6="RDP"),Ruler!E$9,IF(AND(All!$V6="P5",All!$AE6="RDP"),Ruler!E$10,IF(AND(All!$V6="P6",All!$AE6="RDP"),Ruler!E$11,IF(AND(All!$V6="P7",All!$AE6="RDP"),Ruler!E$12,IF(AND(All!$V6="P8",All!$AE6="RDP"),Ruler!E$13,IF(AND(All!$V6="P9",All!$AE6="RDP"),Ruler!E$14,IF(AND(All!$V6="P1",All!$AE6="RMS"),Ruler!E$6,IF(AND(All!$V6="P2",All!$AE6="RMS"),Ruler!E$15,IF(AND(All!$V6="P3",All!$AE6="RMS"),Ruler!E$16,IF(AND(All!$V6="P4",All!$AE6="RMS"),Ruler!E$17,IF(AND(All!$V6="P5",All!$AE6="RMS"),Ruler!E$18,IF(AND(All!$V6="P6",All!$AE6="RMS"),Ruler!E$19,IF(AND(All!$V6="P7",All!$AE6="RMS"),Ruler!E$20,IF(AND(All!$V6="P8",All!$AE6="RMS"),Ruler!E$21,IF(AND(All!$V6="P9",All!$AE6="RMS"),Ruler!E$22,IF(AND(All!$V6="P1",All!$AE6="RSS"),Ruler!E$6,IF(AND(All!$V6="P2",All!$AE6="RSS"),Ruler!E$23,IF(AND(All!$V6="P3",All!$AE6="RSS"),Ruler!E$24,IF(AND(All!$V6="P4",All!$AE6="RSS"),Ruler!E$25,IF(AND(All!$V6="P5",All!$AE6="RSS"),Ruler!E$26,IF(AND(All!$V6="P6",All!$AE6="RSS"),Ruler!E$27,IF(AND(All!$V6="P7",All!$AE6="RSS"),Ruler!E$28,IF(AND(All!$V6="P8",All!$AE6="RSS"),Ruler!E$29,IF(AND(All!$V6="P9",All!$AE6="RSS"),Ruler!E$30,0))))))))))))))))))))))))))) -> 0 | BM6: =IF(AND(All!$V6="P1",All!$AE6="RDP"),Ruler!F$6,IF(AND(All!$V6="P2",All!$AE6="RDP"),Ruler!F$7,IF(AND(All!$V6="P3",All!$AE6="RDP"),Ruler!F$8,IF(AND(All!$V6="P4",All!$AE6="RDP"),Ruler!F$9,IF(AND(All!$V6="P5",All!$AE6="RDP"),Ruler!F$10,IF(AND(All!$V6="P6",All!$AE6="RDP"),Ruler!F$11,IF(AND(All!$V6="P7",All!$AE6="RDP"),Ruler!F$12,IF(AND(All!$V6="P8",All!$AE6="RDP"),Ruler!F$13,IF(AND(All!$V6="P9",All!$AE6="RDP"),Ruler!F$14,IF(AND(All!$V6="P1",All!$AE6="RMS"),Ruler!F$6,IF(AND(All!$V6="P2",All!$AE6="RMS"),Ruler!F$15,IF(AND(All!$V6="P3",All!$AE6="RMS"),Ruler!F$16,IF(AND(All!$V6="P4",All!$AE6="RMS"),Ruler!F$17,IF(AND(All!$V6="P5",All!$AE6="RMS"),Ruler!F$18,IF(AND(All!$V6="P6",All!$AE6="RMS"),Ruler!F$19,IF(AND(All!$V6="P7",All!$AE6="RMS"),Ruler!F$20,IF(AND(All!$V6="P8",All!$AE6="RMS"),Ruler!F$21,IF(AND(All!$V6="P9",All!$AE6="RMS"),Ruler!F$22,IF(AND(All!$V6="P1",All!$AE6="RSS"),Ruler!F$6,IF(AND(All!$V6="P2",All!$AE6="RSS"),Ruler!F$23,IF(AND(All!$V6="P3",All!$AE6="RSS"),Ruler!F$24,IF(AND(All!$V6="P4",All!$AE6="RSS"),Ruler!F$25,IF(AND(All!$V6="P5",All!$AE6="RSS"),Ruler!F$26,IF(AND(All!$V6="P6",All!$AE6="RSS"),Ruler!F$27,IF(AND(All!$V6="P7",All!$AE6="RSS"),Ruler!F$28,IF(AND(All!$V6="P8",All!$AE6="RSS"),Ruler!F$29,IF(AND(All!$V6="P9",All!$AE6="RSS"),Ruler!F$30,0))))))))))))))))))))))))))) -> 0 | BN6: =IF(AND(All!$V6="P1",All!$AE6="RDP"),Ruler!G$6,IF(AND(All!$V6="P2",All!$AE6="RDP"),Ruler!G$7,IF(AND(All!$V6="P3",All!$AE6="RDP"),Ruler!G$8,IF(AND(All!$V6="P4",All!$AE6="RDP"),Ruler!G$9,IF(AND(All!$V6="P5",All!$AE6="RDP"),Ruler!G$10,IF(AND(All!$V6="P6",All!$AE6="RDP"),Ruler!G$11,IF(AND(All!$V6="P7",All!$AE6="RDP"),Ruler!G$12,IF(AND(All!$V6="P8",All!$AE6="RDP"),Ruler!G$13,IF(AND(All!$V6="P9",All!$AE6="RDP"),Ruler!G$14,IF(AND(All!$V6="P1",All!$AE6="RMS"),Ruler!G$6,IF(AND(All!$V6="P2",All!$AE6="RMS"),Ruler!G$15,IF(AND(All!$V6="P3",All!$AE6="RMS"),Ruler!G$16,IF(AND(All!$V6="P4",All!$AE6="RMS"),Ruler!G$17,IF(AND(All!$V6="P5",All!$AE6="RMS"),Ruler!G$18,IF(AND(All!$V6="P6",All!$AE6="RMS"),Ruler!G$19,IF(AND(All!$V6="P7",All!$AE6="RMS"),Ruler!G$20,IF(AND(All!$V6="P8",All!$AE6="RMS"),Ruler!G$21,IF(AND(All!$V6="P9",All!$AE6="RMS"),Ruler!G$22,IF(AND(All!$V6="P1",All!$AE6="RSS"),Ruler!G$6,IF(AND(All!$V6="P2",All!$AE6="RSS"),Ruler!G$23,IF(AND(All!$V6="P3",All!$AE6="RSS"),Ruler!G$24,IF(AND(All!$V6="P4",All!$AE6="RSS"),Ruler!G$25,IF(AND(All!$V6="P5",All!$AE6="RSS"),Ruler!G$26,IF(AND(All!$V6="P6",All!$AE6="RSS"),Ruler!G$27,IF(AND(All!$V6="P7",All!$AE6="RSS"),Ruler!G$28,IF(AND(All!$V6="P8",All!$AE6="RSS"),Ruler!G$29,IF(AND(All!$V6="P9",All!$AE6="RSS"),Ruler!G$30,0))))))))))))))))))))))))))) -> 0 | BO6: =IF(AND(All!$V6="P1",All!$AE6="RDP"),Ruler!H$6,IF(AND(All!$V6="P2",All!$AE6="RDP"),Ruler!H$7,IF(AND(All!$V6="P3",All!$AE6="RDP"),Ruler!H$8,IF(AND(All!$V6="P4",All!$AE6="RDP"),Ruler!H$9,IF(AND(All!$V6="P5",All!$AE6="RDP"),Ruler!H$10,IF(AND(All!$V6="P6",All!$AE6="RDP"),Ruler!H$11,IF(AND(All!$V6="P7",All!$AE6="RDP"),Ruler!H$12,IF(AND(All!$V6="P8",All!$AE6="RDP"),Ruler!H$13,IF(AND(All!$V6="P9",All!$AE6="RDP"),Ruler!H$14,IF(AND(All!$V6="P1",All!$AE6="RMS"),Ruler!H$6,IF(AND(All!$V6="P2",All!$AE6="RMS"),Ruler!H$15,IF(AND(All!$V6="P3",All!$AE6="RMS"),Ruler!H$16,IF(AND(All!$V6="P4",All!$AE6="RMS"),Ruler!H$17,IF(AND(All!$V6="P5",All!$AE6="RMS"),Ruler!H$18,IF(AND(All!$V6="P6",All!$AE6="RMS"),Ruler!H$19,IF(AND(All!$V6="P7",All!$AE6="RMS"),Ruler!H$20,IF(AND(All!$V6="P8",All!$AE6="RMS"),Ruler!H$21,IF(AND(All!$V6="P9",All!$AE6="RMS"),Ruler!H$22,IF(AND(All!$V6="P1",All!$AE6="RSS"),Ruler!H$6,IF(AND(All!$V6="P2",All!$AE6="RSS"),Ruler!H$23,IF(AND(All!$V6="P3",All!$AE6="RSS"),Ruler!H$24,IF(AND(All!$V6="P4",All!$AE6="RSS"),Ruler!H$25,IF(AND(All!$V6="P5",All!$AE6="RSS"),Ruler!H$26,IF(AND(All!$V6="P6",All!$AE6="RSS"),Ruler!H$27,IF(AND(All!$V6="P7",All!$AE6="RSS"),Ruler!H$28,IF(AND(All!$V6="P8",All!$AE6="RSS"),Ruler!H$29,IF(AND(All!$V6="P9",All!$AE6="RSS"),Ruler!H$30,0))))))))))))))))))))))))))) -> 0 | BP6: =IF(AND(All!$V6="P1",All!$AE6="RDP"),Ruler!I$6,IF(AND(All!$V6="P2",All!$AE6="RDP"),Ruler!I$7,IF(AND(All!$V6="P3",All!$AE6="RDP"),Ruler!I$8,IF(AND(All!$V6="P4",All!$AE6="RDP"),Ruler!I$9,IF(AND(All!$V6="P5",All!$AE6="RDP"),Ruler!I$10,IF(AND(All!$V6="P6",All!$AE6="RDP"),Ruler!I$11,IF(AND(All!$V6="P7",All!$AE6="RDP"),Ruler!I$12,IF(AND(All!$V6="P8",All!$AE6="RDP"),Ruler!I$13,IF(AND(All!$V6="P9",All!$AE6="RDP"),Ruler!I$14,IF(AND(All!$V6="P1",All!$AE6="RMS"),Ruler!I$6,IF(AND(All!$V6="P2",All!$AE6="RMS"),Ruler!I$15,IF(AND(All!$V6="P3",All!$AE6="RMS"),Ruler!I$16,IF(AND(All!$V6="P4",All!$AE6="RMS"),Ruler!I$17,IF(AND(All!$V6="P5",All!$AE6="RMS"),Ruler!I$18,IF(AND(All!$V6="P6",All!$AE6="RMS"),Ruler!I$19,IF(AND(All!$V6="P7",All!$AE6="RMS"),Ruler!I$20,IF(AND(All!$V6="P8",All!$AE6="RMS"),Ruler!I$21,IF(AND(All!$V6="P9",All!$AE6="RMS"),Ruler!I$22,IF(AND(All!$V6="P1",All!$AE6="RSS"),Ruler!I$6,IF(AND(All!$V6="P2",All!$AE6="RSS"),Ruler!I$23,IF(AND(All!$V6="P3",All!$AE6="RSS"),Ruler!I$24,IF(AND(All!$V6="P4",All!$AE6="RSS"),Ruler!I$25,IF(AND(All!$V6="P5",All!$AE6="RSS"),Ruler!I$26,IF(AND(All!$V6="P6",All!$AE6="RSS"),Ruler!I$27,IF(AND(All!$V6="P7",All!$AE6="RSS"),Ruler!I$28,IF(AND(All!$V6="P8",All!$AE6="RSS"),Ruler!I$29,IF(AND(All!$V6="P9",All!$AE6="RSS"),Ruler!I$30,0))))))))))))))))))))))))))) -> 0 | BQ6: =IF(AND(All!$V6="P1",All!$AE6="RDP"),Ruler!J$6,IF(AND(All!$V6="P2",All!$AE6="RDP"),Ruler!J$7,IF(AND(All!$V6="P3",All!$AE6="RDP"),Ruler!J$8,IF(AND(All!$V6="P4",All!$AE6="RDP"),Ruler!J$9,IF(AND(All!$V6="P5",All!$AE6="RDP"),Ruler!J$10,IF(AND(All!$V6="P6",All!$AE6="RDP"),Ruler!J$11,IF(AND(All!$V6="P7",All!$AE6="RDP"),Ruler!J$12,IF(AND(All!$V6="P8",All!$AE6="RDP"),Ruler!J$13,IF(AND(All!$V6="P9",All!$AE6="RDP"),Ruler!J$14,IF(AND(All!$V6="P1",All!$AE6="RMS"),Ruler!J$6,IF(AND(All!$V6="P2",All!$AE6="RMS"),Ruler!J$15,IF(AND(All!$V6="P3",All!$AE6="RMS"),Ruler!J$16,IF(AND(All!$V6="P4",All!$AE6="RMS"),Ruler!J$17,IF(AND(All!$V6="P5",All!$AE6="RMS"),Ruler!J$18,IF(AND(All!$V6="P6",All!$AE6="RMS"),Ruler!J$19,IF(AND(All!$V6="P7",All!$AE6="RMS"),Ruler!J$20,IF(AND(All!$V6="P8",All!$AE6="RMS"),Ruler!J$21,IF(AND(All!$V6="P9",All!$AE6="RMS"),Ruler!J$22,IF(AND(All!$V6="P1",All!$AE6="RSS"),Ruler!J$6,IF(AND(All!$V6="P2",All!$AE6="RSS"),Ruler!J$23,IF(AND(All!$V6="P3",All!$AE6="RSS"),Ruler!J$24,IF(AND(All!$V6="P4",All!$AE6="RSS"),Ruler!J$25,IF(AND(All!$V6="P5",All!$AE6="RSS"),Ruler!J$26,IF(AND(All!$V6="P6",All!$AE6="RSS"),Ruler!J$27,IF(AND(All!$V6="P7",All!$AE6="RSS"),Ruler!J$28,IF(AND(All!$V6="P8",All!$AE6="RSS"),Ruler!J$29,IF(AND(All!$V6="P9",All!$AE6="RSS"),Ruler!J$30,0))))))))))))))))))))))))))) -> 0 | BR6: =IF(AND(All!$V6="P1",All!$AE6="RDP"),Ruler!K$6,IF(AND(All!$V6="P2",All!$AE6="RDP"),Ruler!K$7,IF(AND(All!$V6="P3",All!$AE6="RDP"),Ruler!K$8,IF(AND(All!$V6="P4",All!$AE6="RDP"),Ruler!K$9,IF(AND(All!$V6="P5",All!$AE6="RDP"),Ruler!K$10,IF(AND(All!$V6="P6",All!$AE6="RDP"),Ruler!K$11,IF(AND(All!$V6="P7",All!$AE6="RDP"),Ruler!K$12,IF(AND(All!$V6="P8",All!$AE6="RDP"),Ruler!K$13,IF(AND(All!$V6="P9",All!$AE6="RDP"),Ruler!K$14,IF(AND(All!$V6="P1",All!$AE6="RMS"),Ruler!K$6,IF(AND(All!$V6="P2",All!$AE6="RMS"),Ruler!K$15,IF(AND(All!$V6="P3",All!$AE6="RMS"),Ruler!K$16,IF(AND(All!$V6="P4",All!$AE6="RMS"),Ruler!K$17,IF(AND(All!$V6="P5",All!$AE6="RMS"),Ruler!K$18,IF(AND(All!$V6="P6",All!$AE6="RMS"),Ruler!K$19,IF(AND(All!$V6="P7",All!$AE6="RMS"),Ruler!K$20,IF(AND(All!$V6="P8",All!$AE6="RMS"),Ruler!K$21,IF(AND(All!$V6="P9",All!$AE6="RMS"),Ruler!K$22,IF(AND(All!$V6="P1",All!$AE6="RSS"),Ruler!K$6,IF(AND(All!$V6="P2",All!$AE6="RSS"),Ruler!K$23,IF(AND(All!$V6="P3",All!$AE6="RSS"),Ruler!K$24,IF(AND(All!$V6="P4",All!$AE6="RSS"),Ruler!K$25,IF(AND(All!$V6="P5",All!$AE6="RSS"),Ruler!K$26,IF(AND(All!$V6="P6",All!$AE6="RSS"),Ruler!K$27,IF(AND(All!$V6="P7",All!$AE6="RSS"),Ruler!K$28,IF(AND(All!$V6="P8",All!$AE6="RSS"),Ruler!K$29,IF(AND(All!$V6="P9",All!$AE6="RSS"),Ruler!K$30,0))))))))))))))))))))))))))) -> 0 | BS6: =IF(AND(All!$V6="P1",All!$AE6="RDP"),Ruler!L$6,IF(AND(All!$V6="P2",All!$AE6="RDP"),Ruler!L$7,IF(AND(All!$V6="P3",All!$AE6="RDP"),Ruler!L$8,IF(AND(All!$V6="P4",All!$AE6="RDP"),Ruler!L$9,IF(AND(All!$V6="P5",All!$AE6="RDP"),Ruler!L$10,IF(AND(All!$V6="P6",All!$AE6="RDP"),Ruler!L$11,IF(AND(All!$V6="P7",All!$AE6="RDP"),Ruler!L$12,IF(AND(All!$V6="P8",All!$AE6="RDP"),Ruler!L$13,IF(AND(All!$V6="P9",All!$AE6="RDP"),Ruler!L$14,IF(AND(All!$V6="P1",All!$AE6="RMS"),Ruler!L$6,IF(AND(All!$V6="P2",All!$AE6="RMS"),Ruler!L$15,IF(AND(All!$V6="P3",All!$AE6="RMS"),Ruler!L$16,IF(AND(All!$V6="P4",All!$AE6="RMS"),Ruler!L$17,IF(AND(All!$V6="P5",All!$AE6="RMS"),Ruler!L$18,IF(AND(All!$V6="P6",All!$AE6="RMS"),Ruler!L$19,IF(AND(All!$V6="P7",All!$AE6="RMS"),Ruler!L$20,IF(AND(All!$V6="P8",All!$AE6="RMS"),Ruler!L$21,IF(AND(All!$V6="P9",All!$AE6="RMS"),Ruler!L$22,IF(AND(All!$V6="P1",All!$AE6="RSS"),Ruler!L$6,IF(AND(All!$V6="P2",All!$AE6="RSS"),Ruler!L$23,IF(AND(All!$V6="P3",All!$AE6="RSS"),Ruler!L$24,IF(AND(All!$V6="P4",All!$AE6="RSS"),Ruler!L$25,IF(AND(All!$V6="P5",All!$AE6="RSS"),Ruler!L$26,IF(AND(All!$V6="P6",All!$AE6="RSS"),Ruler!L$27,IF(AND(All!$V6="P7",All!$AE6="RSS"),Ruler!L$28,IF(AND(All!$V6="P8",All!$AE6="RSS"),Ruler!L$29,IF(AND(All!$V6="P9",All!$AE6="RSS"),Ruler!L$30,0))))))))))))))))))))))))))) -> 0 | ... CI6: =IF(AND(All!$V6="P1",All!$AE6="RDP"),Ruler!AB$6,IF(AND(All!$V6="P2",All!$AE6="RDP"),Ruler!AB$7,IF(AND(All!$V6="P3",All!$AE6="RDP"),Ruler!AB$8,IF(AND(All!$V6="P4",All!$AE6="RDP"),Ruler!AB$9,IF(AND(All!$V6="P5",All!$AE6="RDP"),Ruler!AB$10,IF(AND(All!$V6="P6",All!$AE6="RDP"),Ruler!AB$11,IF(AND(All!$V6="P7",All!$AE6="RDP"),Ruler!AB$12,IF(AND(All!$V6="P8",All!$AE6="RDP"),Ruler!AB$13,IF(AND(All!$V6="P9",All!$AE6="RDP"),Ruler!AB$14,IF(AND(All!$V6="P1",All!$AE6="RMS"),Ruler!AB$6,IF(AND(All!$V6="P2",All!$AE6="RMS"),Ruler!AB$15,IF(AND(All!$V6="P3",All!$AE6="RMS"),Ruler!AB$16,IF(AND(All!$V6="P4",All!$AE6="RMS"),Ruler!AB$17,IF(AND(All!$V6="P5",All!$AE6="RMS"),Ruler!AB$18,IF(AND(All!$V6="P6",All!$AE6="RMS"),Ruler!AB$19,IF(AND(All!$V6="P7",All!$AE6="RMS"),Ruler!AB$20,IF(AND(All!$V6="P8",All!$AE6="RMS"),Ruler!AB$21,IF(AND(All!$V6="P9",All!$AE6="RMS"),Ruler!AB$22,IF(AND(All!$V6="P1",All!$AE6="RSS"),Ruler!AB$6,IF(AND(All!$V6="P2",All!$AE6="RSS"),Ruler!AB$23,IF(AND(All!$V6="P3",All!$AE6="RSS"),Ruler!AB$24,IF(AND(All!$V6="P4",All!$AE6="RSS"),Ruler!AB$25,IF(AND(All!$V6="P5",All!$AE6="RSS"),Ruler!AB$26,IF(AND(All!$V6="P6",All!$AE6="RSS"),Ruler!AB$27,IF(AND(All!$V6="P7",All!$AE6="RSS"),Ruler!AB$28,IF(AND(All!$V6="P8",All!$AE6="RSS"),Ruler!AB$29,IF(AND(All!$V6="P9",All!$AE6="RSS"),Ruler!AB$30,0))))))))))))))))))))))))))) -> 0 | DH6: =COUNTIF(Table9[[#This Row],[G-B1]:[G-B12]],"<=0")/12*100 -> 0 | DI6: =COUNTIF(Table9[[#This Row],[G-K1]:[G-K5]],"<=0")/5*100 -> 0 | DJ6: =COUNTIF(Table9[[#This Row],[G-P1]:[G-P5]],"<=0")/5*100 -> 0 | DK6: =COUNTIF(Table9[[#This Row],[G-E1]:[G-E2]],"<=0")/2*100 -> 0 | DL6: =IF(AE6="RDP",(COUNTIF(Table9[[#This Row],[G-B3]],"<=0")+COUNTIF(Table9[[#This Row],[G-B4]],"<=0")+COUNTIF(Table9[[#This Row],[G-B7]],"<=0")+COUNTIF(Table9[[#This Row],[G-B11]],"<=0")+COUNTIF(Table9[[#This Row],[G-K2]],"<=0"))/5*100,IF(AE6="RMS",(COUNTIF(Table9[[#This Row],[G-B4]],"<=0")+COUNTIF(Table9[[#This Row],[G-B5]],"<=0")+COUNTIF(Table9[[#This Row],[G-B10]],"<=0")+COUNTIF(Table9[[#This Row],[G-B12]],"<=0")+COUNTIF(Table9[[#This Row],[G-K2]],"<=0"))/5*100,IF(AE6="RSS",(COUNTIF(Table9[[#This Row],[G-B1]],"<=0")+COUNTIF(Table9[[#This Row],[G-B2]],"<=0")+COUNTIF(Table9[[#This Row],[G-B6]],"<=0")+COUNTIF(Table9[[#This Row],[G-B11]],"<=0")+COUNTIF(Table9[[#This Row],[G-B12]],"<=0"))/5*100,0))) -> 0
